<?xml version='1.0'?>
<sdf version='1.6'>
  <model name='x3'>
    <pose>0 0 0.053302 0 0 0</pose>
    <link name='X3/base_link'>
      <pose frame=''>0 0 0 0 -0 0</pose>
      <inertial>
        <pose frame=''>0 0 0 0 -0 0</pose>
        <mass>1.5</mass>
        <inertia>
          <ixx>0.0347563</ixx>
          <ixy>0</ixy>
          <ixz>0</ixz>
          <iyy>0.07</iyy>
          <iyz>0</iyz>
          <izz>0.0977</izz>
        </inertia>
      </inertial>
      <collision name='X3/base_link_inertia_collision'>
        <pose frame=''>0 0 0 0 -0 0</pose>
        <geometry>
          <box>
            <size>0.47 0.47 0.11</size>
          </box>
        </geometry>
      </collision>
      <visual name='X3/base_link_inertia_visual'>
        <pose frame=''>0 0 0 0 -0 0</pose>
        <geometry>
          <mesh>
            <scale>1 1 1</scale>
            <uri>/home/arash/ros2_ws/src/hybrid_pkg/model/X3UAV/meshes/x3.dae</uri>
          </mesh>
        </geometry>
      </visual>
      <sensor name="imu_sensor" type="imu">
                <always_on>1</always_on>
                <update_rate>250</update_rate>
                <imu>
                    <enable_orientation>0</enable_orientation>
                    <angular_velocity>
                        <x>
                            <noise type="gaussian">
                                <mean>0</mean>
                                <stddev>0.009</stddev>
                                <bias_mean>0.00075</bias_mean>
                                <bias_stddev>0.005</bias_stddev>
                                <dynamic_bias_stddev>0.00002</dynamic_bias_stddev>
				<dynamic_bias_correlation_time>400.0</dynamic_bias_correlation_time>
				<precision>0.00025</precision>
                            </noise>
                        </x>
                        <y>
                            <noise type="gaussian">
                                <mean>0</mean>
                                <stddev>0.009</stddev>
                                <bias_mean>0.00075</bias_mean>
                                <bias_stddev>0.005</bias_stddev>
                                <dynamic_bias_stddev>0.00002</dynamic_bias_stddev>
				<dynamic_bias_correlation_time>400.0</dynamic_bias_correlation_time>
				<precision>0.00025</precision>
                            </noise>
                        </y>
                        <z>
                            <noise type="gaussian">
                                <mean>0</mean>
                                <stddev>0.009</stddev>
                                <bias_mean>0.00075</bias_mean>
                                <bias_stddev>0.005</bias_stddev>
                                <dynamic_bias_stddev>0.00002</dynamic_bias_stddev>
				<dynamic_bias_correlation_time>400.0</dynamic_bias_correlation_time>
				<precision>0.00025</precision>
                            </noise>
                        </z>
                    </angular_velocity>
                    <linear_acceleration>
                        <x>
                            <noise type="gaussian">
                                <mean>0</mean>
                                <stddev>0.021</stddev>
                                <bias_mean>0.05</bias_mean>
                                <bias_stddev>0.0075</bias_stddev>
                                <dynamic_bias_stddev>0.000375</dynamic_bias_stddev>
				<dynamic_bias_correlation_time>175.0</dynamic_bias_correlation_time>
				<precision>0.005</precision>
                            </noise>
                        </x>
                        <y>
                            <noise type="gaussian">
                                <mean>0</mean>
                                <stddev>0.021</stddev>
                                <bias_mean>0.05</bias_mean>
                                <bias_stddev>0.0075</bias_stddev>
                                <dynamic_bias_stddev>0.000375</dynamic_bias_stddev>
				<dynamic_bias_correlation_time>175.0</dynamic_bias_correlation_time>
				<precision>0.005</precision>
                            </noise>
                        </y>
                        <z>
                            <noise type="gaussian">
                                <mean>0</mean>
                                <stddev>0.021</stddev>
                                <bias_mean>0.05</bias_mean>
                                <bias_stddev>0.0075</bias_stddev>
                                <dynamic_bias_stddev>0.000375</dynamic_bias_stddev>
				<dynamic_bias_correlation_time>175.0</dynamic_bias_correlation_time>
				<precision>0.005</precision>
                            </noise>
                        </z>
                    </linear_acceleration>
                </imu>

            </sensor>
            <sensor name="air_pressure" type="air_pressure">
                <always_on>1</always_on>
                <update_rate>20</update_rate>
                <air_pressure>
                    <reference_altitude>0</reference_altitude>
                    <noise type="gaussian">
                        <mean>0.00000008</mean>
                    </noise>
                </air_pressure>
            </sensor>
            <sensor name="magnetometer" type="magnetometer">
                <always_on>1</always_on>
                <update_rate>20</update_rate>
                <magnetometer>
                    <x>
                        <noise type="gaussian">
                            <mean>0.000000080</mean>
                            <bias_mean>0.000000400</bias_mean>
                        </noise>
                    </x>
                    <y>
                        <noise type="gaussian">
                            <mean>0.000000080</mean>
                            <bias_mean>0.000000400</bias_mean>
                        </noise>
                    </y>
                    <z>
                        <noise type="gaussian">
                            <mean>0.000000080</mean>
                            <bias_mean>0.000000400</bias_mean>
                        </noise>
                    </z>
                </magnetometer>
            </sensor>

            <visual name="camera_visual">
                <pose>0.1 0 0 0 0 0</pose>
                <geometry>
                    <box>
                        <size>0.02 0.02 0.02</size>
                    </box>
                </geometry>
            </visual>

            <sensor name="camera_front" type="rgbd_camera">
                <pose>0.1 0 0 0 0 0</pose>
                <always_on>1</always_on>
                <update_rate>20</update_rate>
                <camera name="camera_front">
                    <horizontal_fov>1.0472</horizontal_fov>
                    <lens>
                        <intrinsics>
                          <!-- fx = fy = width / ( 2 * tan (hfov / 2 ) ) -->
                          <fx>277.1</fx>
                          <fy>277.1</fy>
                          <!-- cx = ( width + 1 ) / 2 -->
                          <cx>160.5</cx>
                          <!-- cy = ( height + 1 ) / 2 -->
                          <cy>120.5</cy>
                          <s>0</s>
                        </intrinsics>
                    </lens>
                    <distortion>
                        <k1>0.0</k1>
                        <k2>0.0</k2>
                        <k3>0.0</k3>
                        <p1>0.0</p1>
                        <p2>0.0</p2>
                        <center>0.5 0.5</center>
                    </distortion>
                    <image>
                        <width>320</width>
                        <height>240</height>
                        <format>R8G8B8</format>
                    </image>
                    <clip>
                        <near>0.01</near>
                        <far>300</far>
                    </clip>
                    <depth_camera>
                      <clip>
                        <near>0.1</near>
                        <far>10</far>
                      </clip>
                    </depth_camera>
                    <noise>
                        <type>gaussian</type>
                        <mean>0</mean>
                        <stddev>0.007</stddev>
                    </noise>
                </camera>
            </sensor>
        
    </link>
    <link name='X3/rotor_0'>
      <pose frame=''>0.13 -0.22 0.023 0 -0 0</pose>
      <inertial>
        <pose frame=''>0 0 0 0 -0 0</pose>
        <mass>0.005</mass>
        <inertia>
          <ixx>9.75e-07</ixx>
          <ixy>0</ixy>
          <ixz>0</ixz>
          <iyy>4.17041e-05</iyy>
          <iyz>0</iyz>
          <izz>4.26041e-05</izz>
        </inertia>
      </inertial>
      <collision name='X3/rotor_0_collision'>
        <pose frame=''>0 0 0 0 -0 0</pose>
        <geometry>
          <cylinder>
            <length>0.005</length>
            <radius>0.1</radius>
          </cylinder>
        </geometry>
        <surface>
          <contact>
            <ode/>
          </contact>
          <friction>
            <ode/>
          </friction>
        </surface>
      </collision>
      <visual name='X3/rotor_0_visual'>
        <pose frame=''>0 0 0 0 -0 0</pose>
        <geometry>
          <mesh>
            <scale>0.1 0.1 0.1</scale>
            <uri>/home/arash/ros2_ws/src/hybrid_pkg/model/X3UAV/meshes/propeller_ccw.dae</uri>
          </mesh>
        </geometry>
        <material>
          <script>
            <name>Gazebo/Blue</name>
            <uri>file://media/materials/scripts/gazebo.material</uri>
          </script>
        </material>
      </visual>
      <gravity>1</gravity>
      <velocity_decay/>
    </link>
    <joint name='X3/rotor_0_joint' type='revolute'>
      <child>X3/rotor_0</child>
      <parent>X3/base_link</parent>
      <axis>
        <xyz>0 0 1</xyz>
        <limit>
          <lower>-1e+16</lower>
          <upper>1e+16</upper>
        </limit>
        <dynamics>
          <spring_reference>0</spring_reference>
          <spring_stiffness>0</spring_stiffness>
        </dynamics>
        <use_parent_model_frame>1</use_parent_model_frame>
      </axis>
    </joint>
    <link name='X3/rotor_1'>
      <pose frame=''>-0.13 0.2 0.023 0 -0 0</pose>
      <inertial>
        <pose frame=''>0 0 0 0 -0 0</pose>
        <mass>0.005</mass>
        <inertia>
          <ixx>9.75e-07</ixx>
          <ixy>0</ixy>
          <ixz>0</ixz>
          <iyy>4.17041e-05</iyy>
          <iyz>0</iyz>
          <izz>4.26041e-05</izz>
        </inertia>
      </inertial>
      <collision name='X3/rotor_1_collision'>
        <pose frame=''>0 0 0 0 -0 0</pose>
        <geometry>
          <cylinder>
            <length>0.005</length>
            <radius>0.1</radius>
          </cylinder>
        </geometry>
        <surface>
          <contact>
            <ode/>
          </contact>
          <friction>
            <ode/>
          </friction>
        </surface>
      </collision>
      <visual name='X3/rotor_1_visual'>
        <pose frame=''>0 0 0 0 -0 0</pose>
        <geometry>
          <mesh>
            <scale>0.1 0.1 0.1</scale>
            <uri>/home/arash/ros2_ws/src/hybrid_pkg/model/X3UAV/meshes/propeller_ccw.dae</uri>
          </mesh>
        </geometry>
        <material>
          <script>
            <name>Gazebo/Red</name>
            <uri>file://media/materials/scripts/gazebo.material</uri>
          </script>
        </material>
      </visual>
      <gravity>1</gravity>
      <velocity_decay/>
    </link>
    <joint name='X3/rotor_1_joint' type='revolute'>
      <child>X3/rotor_1</child>
      <parent>X3/base_link</parent>
      <axis>
        <xyz>0 0 1</xyz>
        <limit>
          <lower>-1e+16</lower>
          <upper>1e+16</upper>
        </limit>
        <dynamics>
          <spring_reference>0</spring_reference>
          <spring_stiffness>0</spring_stiffness>
        </dynamics>
        <use_parent_model_frame>1</use_parent_model_frame>
      </axis>
    </joint>
    <link name='X3/rotor_2'>
      <pose frame=''>0.13 0.22 0.023 0 -0 0</pose>
      <inertial>
        <pose frame=''>0 0 0 0 -0 0</pose>
        <mass>0.005</mass>
        <inertia>
          <ixx>9.75e-07</ixx>
          <ixy>0</ixy>
          <ixz>0</ixz>
          <iyy>4.17041e-05</iyy>
          <iyz>0</iyz>
          <izz>4.26041e-05</izz>
        </inertia>
      </inertial>
      <collision name='X3/rotor_2_collision'>
        <pose frame=''>0 0 0 0 -0 0</pose>
        <geometry>
          <cylinder>
            <length>0.005</length>
            <radius>0.1</radius>
          </cylinder>
        </geometry>
        <surface>
          <contact>
            <ode/>
          </contact>
          <friction>
            <ode/>
          </friction>
        </surface>
      </collision>
      <visual name='X3/rotor_2_visual'>
        <pose frame=''>0 0 0 0 -0 0</pose>
        <geometry>
          <mesh>
            <scale>0.1 0.1 0.1</scale>
            <uri>/home/arash/ros2_ws/src/hybrid_pkg/model/X3UAV/meshes/propeller_cw.dae</uri>
          </mesh>
        </geometry>
        <material>
          <script>
            <name>Gazebo/Blue</name>
            <uri>file://media/materials/scripts/gazebo.material</uri>
          </script>
        </material>
      </visual>
      <gravity>1</gravity>
      <velocity_decay/>
    </link>
    <joint name='X3/rotor_2_joint' type='revolute'>
      <child>X3/rotor_2</child>
      <parent>X3/base_link</parent>
      <axis>
        <xyz>0 0 1</xyz>
        <limit>
          <lower>-1e+16</lower>
          <upper>1e+16</upper>
        </limit>
        <dynamics>
          <spring_reference>0</spring_reference>
          <spring_stiffness>0</spring_stiffness>
        </dynamics>
        <use_parent_model_frame>1</use_parent_model_frame>
      </axis>
    </joint>
    <link name='X3/rotor_3'>
      <pose frame=''>-0.13 -0.2 0.023 0 -0 0</pose>
      <inertial>
        <pose frame=''>0 0 0 0 -0 0</pose>
        <mass>0.005</mass>
        <inertia>
          <ixx>9.75e-07</ixx>
          <ixy>0</ixy>
          <ixz>0</ixz>
          <iyy>4.17041e-05</iyy>
          <iyz>0</iyz>
          <izz>4.26041e-05</izz>
        </inertia>
      </inertial>
      <collision name='X3/rotor_3_collision'>
        <pose frame=''>0 0 0 0 -0 0</pose>
        <geometry>
          <cylinder>
            <length>0.005</length>
            <radius>0.1</radius>
          </cylinder>
        </geometry>
        <surface>
          <contact>
            <ode/>
          </contact>
          <friction>
            <ode/>
          </friction>
        </surface>
      </collision>
      <visual name='X3/rotor_3_visual'>
        <pose frame=''>0 0 0 0 -0 0</pose>
        <geometry>
          <mesh>
            <scale>0.1 0.1 0.1</scale>
            <uri>/home/arash/ros2_ws/src/hybrid_pkg/model/X3UAV/meshes/propeller_cw.dae</uri>
          </mesh>
        </geometry>
        <material>
          <script>
            <name>Gazebo/Red</name>
            <uri>file://media/materials/scripts/gazebo.material</uri>
          </script>
        </material>
      </visual>
      <gravity>1</gravity>
      <velocity_decay/>
    </link>
    <joint name='X3/rotor_3_joint' type='revolute'>
      <child>X3/rotor_3</child>
      <parent>X3/base_link</parent>
      <axis>
        <xyz>0 0 1</xyz>
        <limit>
          <lower>-1e+16</lower>
          <upper>1e+16</upper>
        </limit>
        <dynamics>
          <spring_reference>0</spring_reference>
          <spring_stiffness>0</spring_stiffness>
        </dynamics>
        <use_parent_model_frame>1</use_parent_model_frame>
      </axis>
    </joint>
  </model>
</sdf>
